<?xml version="1.0"?>
<robot xmlns:xacro="http://wiki.ros.org/xacro" name="ur">

	<link name="suction_base_link">
		<inertial>
			<origin xyz="0 0 -0.026287" rpy="0 0 0"/>
			<mass value="0.10731"/>
			<inertia ixx="0.00011185" ixy="0.0" ixz="0.0" iyy="0.00011185" iyz="0.0" izz="4.9673E-05"/>
		</inertial>
		<collision>
			<origin xyz="0 0 0" rpy="0 0 0"/>
			<geometry>
				<mesh filename="file://$(find mit_robot_description)/meshes/suction_gripper.STL"/>
			</geometry>
		</collision>
		<visual>
			<origin xyz="0 0 0" rpy="0 0 0"/>
			<geometry>
				<mesh filename="file://$(find mit_robot_description)/meshes/suction_gripper.STL"/>
			</geometry>
			<material name="white"/>
		</visual>
	</link>

	<joint name="suction_base_joint" type="revolute">
		<axis xyz="1 0 0" />
		<parent link="wrist_3_link" />
		<child link="suction_base_link" />
		<origin rpy="0 ${pi} 0" xyz="0 0 0" />
		<limit effort="50" velocity="50" lower="-${pi}" upper="${pi}" />
		<dynamics damping="0.0" friction="10"/>
	</joint>

	<ros2_control name="GazeboSystem" type="system">
    <hardware>
      <plugin>gazebo_ros2_control/GazeboSystem</plugin>
    </hardware>

		<joint name="suction_base_joint">
      <command_interface name="position"/>
      <state_interface name="position"/>
      <state_interface name="velocity"/>
      <state_interface name="effort"/>
    </joint>
	</ros2_control>

	<transmission name="suction_base_trans">
		<type>transmission_interface/SimpleTransmission</type>
		<joint name="suction_base_joint">
			<hardwareInterface>hardware_interface/PositionJointInterface</hardwareInterface>
		</joint>
		<actuator name="suction_base_motor">
			<mechanicalReduction>1</mechanicalReduction>
		</actuator>
	</transmission>


</robot>
